<?xml version="1.0" encoding="utf-8"?>
<robot name="ur5">
    <gazebo>
        <plugin name="gazebo_ros_control" filename="libgazebo_ros_control.so">
            <!-- <robotNamespace>/</robotNamespace> -->
        </plugin>
    </gazebo>
    <link name="base_link">
        <visual>
            <origin rpy="0 0 3.141592653589793" xyz="0 0 0" />
            <geometry>
                <mesh filename="package://ur_description/meshes/ur5/visual/base.dae" />
            </geometry>
            <material name="LightGrey">
                <color rgba="0.7 0.7 0.7 1.0" />
            </material>
        </visual>
        <collision>
            <origin rpy="0 0 3.141592653589793" xyz="0 0 0" />
            <geometry>
                <mesh filename="package://ur_description/meshes/ur5/collision/base.stl" />
            </geometry>
        </collision>
        <inertial>
            <mass value="4.0" />
            <origin rpy="0 0 0" xyz="0 0 0" />
            <inertia ixx="0.00443333156" ixy="0.0" ixz="0.0" iyy="0.00443333156" iyz="0.0"
                izz="0.0072" />
        </inertial>
    </link>
    <joint name="shoulder_pan_joint" type="revolute">
        <parent link="base_link" />
        <child link="shoulder_link" />
        <origin rpy="0.0 0.0 0.0" xyz="0.0 0.0 0.089159" />
        <axis xyz="0 0 1" />
        <limit effort="150.0" lower="-3.14159265" upper="3.14159265" velocity="3.15" />
        <dynamics damping="0.0" friction="0.0" />
    </joint>
    <link name="shoulder_link">
        <visual>
            <origin rpy="0 0 3.141592653589793" xyz="0 0 0" />
            <geometry>
                <mesh filename="package://ur_description/meshes/ur5/visual/shoulder.dae" />
            </geometry>
            <material name="LightGrey">
                <color rgba="0.7 0.7 0.7 1.0" />
            </material>
        </visual>
        <collision>
            <origin rpy="0 0 3.141592653589793" xyz="0 0 0" />
            <geometry>
                <mesh filename="package://ur_description/meshes/ur5/collision/shoulder.stl" />
            </geometry>
        </collision>
        <inertial>
            <mass value="3.7" />
            <origin rpy="0 0 0" xyz="0 0 0" />
            <inertia ixx="0.014972352344389999" ixy="0.0" ixz="0.0" iyy="0.014972352344389999"
                iyz="0.0" izz="0.01040625" />
        </inertial>
    </link>
    <joint name="shoulder_lift_joint" type="revolute">
        <parent link="shoulder_link" />
        <child link="upper_arm_link" />
        <origin rpy="1.570796327 0 0" xyz="0 0 0" />
        <axis xyz="0 0 1" />
        <limit effort="150.0" lower="-6.283185307179586" upper="6.283185307179586"
            velocity="3.141592653589793" />
        <dynamics damping="0" friction="0" />
    </joint>
    <link name="upper_arm_link">
        <visual>
            <origin rpy="1.5707963267948966 0 -1.5707963267948966" xyz="0 0 0.13585" />
            <geometry>
                <mesh filename="package://ur_description/meshes/ur5/visual/upperarm.dae" />
            </geometry>
            <material name="LightGrey">
                <color rgba="0.7 0.7 0.7 1.0" />
            </material>
        </visual>
        <collision>
            <origin rpy="1.5707963267948966 0 -1.5707963267948966" xyz="0 0 0.13585" />
            <geometry>
                <mesh filename="package://ur_description/meshes/ur5/collision/upperarm.stl" />
            </geometry>
        </collision>
        <inertial>
            <mass value="8.393" />
            <origin rpy="0 1.5707963267948966 0" xyz="-0.2125 0.0 0.136" />
            <inertia ixx="0.1338857818623325" ixy="0.0" ixz="0.0" iyy="0.1338857818623325" iyz="0.0"
                izz="0.0151074" />
        </inertial>
    </link>
    <joint name="elbow_joint" type="revolute">
        <parent link="upper_arm_link" />
        <child link="forearm_link" />
        <origin rpy="0 0 0" xyz="-0.425 0 0" />
        <axis xyz="0 0 1" />
        <limit effort="150.0" lower="-3.141592653589793" upper="3.141592653589793"
            velocity="3.141592653589793" />
        <dynamics damping="0" friction="0" />
    </joint>
    <link name="forearm_link">
        <visual>
            <origin rpy="1.5707963267948966 0 -1.5707963267948966" xyz="0 0 0.0165" />
            <geometry>
                <mesh filename="package://ur_description/meshes/ur5/visual/forearm.dae" />
            </geometry>
            <material name="LightGrey">
                <color rgba="0.7 0.7 0.7 1.0" />
            </material>
        </visual>
        <collision>
            <origin rpy="1.5707963267948966 0 -1.5707963267948966" xyz="0 0 0.0165" />
            <geometry>
                <mesh filename="package://ur_description/meshes/ur5/collision/forearm.stl" />
            </geometry>
        </collision>
        <inertial>
            <mass value="2.275" />
            <origin rpy="0 1.5707963267948966 0" xyz="-0.196125 0.0 0.0165" />
            <inertia ixx="0.03121679102890359" ixy="0.0" ixz="0.0" iyy="0.03121679102890359"
                iyz="0.0" izz="0.004095" />
        </inertial>
    </link>
    <joint name="wrist_1_joint" type="revolute">
        <parent link="forearm_link" />
        <child link="wrist_1_link" />
        <origin rpy="0 0 0" xyz="-0.39225 0 0.10915" />
        <axis xyz="0 0 1" />
        <limit effort="28.0" lower="-6.283185307179586" upper="6.283185307179586"
            velocity="3.141592653589793" />
        <dynamics damping="0" friction="0" />
    </joint>
    <link name="wrist_1_link">
        <visual>
            <!-- TODO: Move this to a parameter -->
            <origin rpy="1.5707963267948966 0 0" xyz="0 0 -0.093" />
            <geometry>
                <mesh filename="package://ur_description/meshes/ur5/visual/wrist1.dae" />
            </geometry>
            <material name="LightGrey">
                <color rgba="0.7 0.7 0.7 1.0" />
            </material>
        </visual>
        <collision>
            <origin rpy="1.5707963267948966 0 0" xyz="0 0 -0.093" />
            <geometry>
                <mesh filename="package://ur_description/meshes/ur5/collision/wrist1.stl" />
            </geometry>
        </collision>
        <inertial>
            <mass value="1.219" />
            <origin rpy="0 0 0" xyz="0 0 0" />
            <inertia ixx="0.0020138887777775" ixy="0.0" ixz="0.0" iyy="0.0020138887777775" iyz="0.0"
                izz="0.0021942" />
        </inertial>
    </link>
    <joint name="wrist_2_joint" type="revolute">
        <parent link="wrist_1_link" />
        <child link="wrist_2_link" />
        <origin rpy="1.570796327 0 0" xyz="0 -0.09465 -1.941303950897609e-11" />
        <axis xyz="0 0 1" />
        <limit effort="28.0" lower="-6.283185307179586" upper="6.283185307179586"
            velocity="3.141592653589793" />
        <dynamics damping="0" friction="0" />
    </joint>
    <link name="wrist_2_link">
        <visual>
            <origin rpy="0 0 0" xyz="0 0 -0.095" />
            <geometry>
                <mesh filename="package://ur_description/meshes/ur5/visual/wrist2.dae" />
            </geometry>
            <material name="LightGrey">
                <color rgba="0.7 0.7 0.7 1.0" />
            </material>
        </visual>
        <collision>
            <origin rpy="0 0 0" xyz="0 0 -0.095" />
            <geometry>
                <mesh filename="package://ur_description/meshes/ur5/collision/wrist2.stl" />
            </geometry>
        </collision>
        <inertial>
            <mass value="1.219" />
            <origin rpy="0 0 0" xyz="0 0 0" />
            <inertia ixx="0.0018310388509175" ixy="0.0" ixz="0.0" iyy="0.0018310388509175" iyz="0.0"
                izz="0.0021942" />
        </inertial>
    </link>
    <joint name="wrist_3_joint" type="revolute">
        <parent link="wrist_2_link" />
        <child link="wrist_3_link" />
        <origin rpy="1.570796326589793 3.141592653589793 3.141592653589793"
            xyz="0 0.0823 -1.688001216681175e-11" />
        <axis xyz="0 0 1" />
        <limit effort="28.0" lower="-6.283185307179586" upper="6.283185307179586"
            velocity="3.141592653589793" />
        <dynamics damping="0" friction="0" />
    </joint>

    <link name="wrist_3_link">
        <visual>
            <origin rpy="1.5707963267948966 0 0" xyz="0 0 -0.0818" />
            <geometry>
                <mesh filename="package://ur_description/meshes/ur5/visual/wrist3.dae" />
            </geometry>
            <material name="LightGrey">
                <color rgba="0.7 0.7 0.7 1.0" />
            </material>
        </visual>
        <collision>
            <origin rpy="1.5707963267948966 0 0" xyz="0 0 -0.0818" />
            <geometry>
                <mesh filename="package://ur_description/meshes/ur5/collision/wrist3.stl" />
            </geometry>
        </collision>
        <inertial>
            <mass value="0.1879" />
            <origin rpy="0 0 0" xyz="0.0 0.0 -0.01525" />
            <inertia ixx="8.062472608343e-05" ixy="0.0" ixz="0.0" iyy="8.062472608343e-05" iyz="0.0"
                izz="0.0001321171875" />
        </inertial>
    </link>

    <joint name="ee_fixed_joint" type="fixed">
        <parent link="wrist_3_link" />
        <child link="ee_link" />
        <origin rpy="0 3.14 0" xyz="0.0 0 0.0" />
        <axis xyz="0 0 1" />
        <limit effort="0" lower="0" upper="0" velocity="0" />
        <dynamics damping="0.0" friction="0.0" />
    </joint>

    <link name="ee_link">
        <visual>
            <geometry>
                <cylinder radius="0.0025" length="0.3" />
            </geometry>
            <material name="Cyan">
                <color rgba="0.0 1.0 1.0 1.0" />
            </material>
            <origin rpy="0 0 0" xyz="0.0 0.0 -0.15" />
        </visual>
        <collision>
            <geometry>
                <cylinder radius="0.0025" length="0.3" />
            </geometry>
            <origin rpy="0 0 0" xyz="0.0 0.0 -0.15" />
        </collision>
        <inertial>
            <mass value="0.1" />
            <origin xyz="0 0 0" rpy="0 0 0" />
            <inertia ixx="0.03" iyy="0.03" izz="0.03" ixy="0.0" ixz="0.0" iyz="0.0" />
        </inertial>
    </link>

    <joint name="camera_joint" type="fixed">
        <parent link="ee_link" />
        <child link="camera_link" />
        <origin xyz="0 0 -0.3" rpy="0 1.570796325 0" />
    </joint>
    <link name="camera_link">
        <gazebo reference="camera_link" />
        <visual>
            <geometry>
                <box size="0.001 0.002 0.002" />
            </geometry>
            <material name="Cyan">
                <color rgba="0.0 1.0 1.0 1.0" />
            </material>
        </visual>
    </link>
    <joint name="camera_optical_joint" type="fixed">
        <parent link="camera_link" />
        <child link="camera_link_optical" />
        <origin xyz="0 0 0.3" rpy="-1.570796325 0 -1.570796325" />
    </joint>
    <link name="camera_link_optical" />
    <gazebo reference="camera_link">
        <material>Gazebo/Red</material>
        <sensor name="camera" type="camera">
            <pose>0 0 0 0 0 0</pose>
            <visualize>true</visualize>
            <update_rate>10</update_rate>
            <camera>
                <horizontal_fov>1.089</horizontal_fov>
                <image>
                    <format>R8G8B8</format>
                    <width>640</width>
                    <height>480</height>
                </image>
                <clip>
                    <near>0.05</near>
                    <far>8.0</far>
                </clip>
            </camera>
            <plugin name="camera_controller" filename="libgazebo_ros_camera.so">
                <frame_name>camera_link_optical</frame_name>
            </plugin>
        </sensor>
    </gazebo>
    <transmission name="shoulder_pan_trans">
        <type>transmission_interface/SimpleTransmission</type>
        <joint name="shoulder_pan_joint">
            <hardwareInterface>hardware_interface/VelocityJointInterface</hardwareInterface>
        </joint>
        <actuator name="shoulder_pan_motor">
            <mechanicalReduction>1</mechanicalReduction>
            <hardwareInterface>hardware_interface/VelocityJointInterface</hardwareInterface>
        </actuator>
    </transmission>
    <transmission name="shoulder_lift_trans">
        <type>transmission_interface/SimpleTransmission</type>
        <joint name="shoulder_lift_joint">
            <hardwareInterface>hardware_interface/VelocityJointInterface</hardwareInterface>
        </joint>
        <actuator name="shoulder_lift_motor">
            <mechanicalReduction>1</mechanicalReduction>
            <hardwareInterface>hardware_interface/VelocityJointInterface</hardwareInterface>
        </actuator>
    </transmission>
    <transmission name="elbow_trans">
        <type>transmission_interface/SimpleTransmission</type>
        <joint name="elbow_joint">
            <hardwareInterface>hardware_interface/VelocityJointInterface</hardwareInterface>
        </joint>
        <actuator name="elbow_motor">
            <mechanicalReduction>1</mechanicalReduction>
            <hardwareInterface>hardware_interface/VelocityJointInterface</hardwareInterface>
        </actuator>
    </transmission>
    <transmission name="wrist_1_trans">
        <type>transmission_interface/SimpleTransmission</type>
        <joint name="wrist_1_joint">
            <hardwareInterface>hardware_interface/VelocityJointInterface</hardwareInterface>
        </joint>
        <actuator name="wrist_1_motor">
            <mechanicalReduction>1</mechanicalReduction>
            <hardwareInterface>hardware_interface/VelocityJointInterface</hardwareInterface>
        </actuator>
    </transmission>
    <transmission name="wrist_2_trans">
        <type>transmission_interface/SimpleTransmission</type>
        <joint name="wrist_2_joint">
            <hardwareInterface>hardware_interface/VelocityJointInterface</hardwareInterface>
        </joint>
        <actuator name="wrist_2_motor">
            <mechanicalReduction>1</mechanicalReduction>
            <hardwareInterface>hardware_interface/VelocityJointInterface</hardwareInterface>
        </actuator>
    </transmission>
    <transmission name="wrist_3_trans">
        <type>transmission_interface/SimpleTransmission</type>
        <joint name="wrist_3_joint">
            <hardwareInterface>hardware_interface/VelocityJointInterface</hardwareInterface>
        </joint>
        <actuator name="wrist_3_motor">
            <mechanicalReduction>1</mechanicalReduction>
            <hardwareInterface>hardware_interface/VelocityJointInterface</hardwareInterface>
        </actuator>
    </transmission>
    <!-- define the ur5's position and orientation in the world coordinate system -->
    <link name="world" />
    <joint name="world_robot_joint" type="fixed">
        <parent link="world" />
        <child link="base_link" />
        <!-- TODO: check base_link name of robot -->
        <origin rpy="0.0 0.0 3.141592653589793" xyz="0.0 0.0 0.05" />
    </joint>
    <joint name="world_table_joint" type="fixed">
        <parent link="world" />
        <child link="table_top" />
        <!-- TODO: check base_link name of robot -->
        <origin rpy="0.0 0.0 0.0" xyz="0.1 1.1 0.025" />
    </joint>
    <joint name="base_link_rcm" type="fixed">
        <parent link="base_link" />
        <child link="rcm_link" />
        <!-- TODO: check base_link name of robot -->
        <origin rpy="0.0 0.0 0.0" xyz="0.04248387 -0.71920688  0.23206623" />
    </joint>
    <link name="rcm_link">
        <visual>
            <geometry>
                <sphere radius="0.006" />
                <!-- Length: 1.5m, Width: 1 m, Thickness: 0.05m -->
            </geometry>
            <material name="Brown">
                <color rgba="0.5 0.3 0.1 1.0" />
                <!-- Brown color -->
            </material>
        </visual>
        <collision>
            <geometry>
                <sphere radius="0.01" />
            </geometry>
        </collision>
        <inertial>
            <mass value="1.0" />
            <!-- Table mass -->
            <inertia ixx="0.01" iyy="0.01" izz="0.01" ixy="0.0" ixz="0.0" iyz="0.0" />
            <origin xyz="0 0 0" rpy="0 0 0" />
        </inertial>
    </link>
    <gazebo reference="rcm_link">
        <material>Gazebo/Yellow</material>
    </gazebo>
    <joint name="base_link_goal" type="fixed">
        <parent link="base_link" />
        <child link="goal_link" />
        <!-- TODO: check base_link name of robot -->
        <!-- test 1 -->
        <!-- <origin rpy="0.0 0.0 0.0" xyz="0.04325266 -1.03956855 0.18399166" /> -->

        <!-- test 1.0 -->
        <origin rpy="0.0 0.0 0.0" xyz="0.05312177 -0.82213129  0.09047495" />
        <!-- test 1.1 -->
        <!-- <origin rpy="0.0 0.0 0.0" xyz="-0.035, -0.970, 0.120" /> -->
        <!-- test 1.2 -->
        <!-- <origin rpy="0.0 0.0 0.0" xyz="0.051 -0.722  0.110" /> -->
        <!-- test 1.3 -->
        <!-- <origin rpy="0.0 0.0 0.0" xyz="0.054 -0.869 0.13" /> -->
        <!-- test 1.4 -->
        <!-- <origin rpy="0.0 0.0 0.0" xyz="-0.164 -0.729 0.2" /> -->
        <!-- test 1.5 -->
        <!-- <origin rpy="0.0 0.0 0.0" xyz="-0.134 -0.799 0.2" /> -->
        <!-- test 1.6 -->
        <!-- <origin rpy="0.0 0.0 0.0" xyz="-0.114 -0.739 0.15" /> -->
        <!-- test 1.7 -->
        <!-- <origin rpy="0.0 0.0 0.0" xyz=-"0.08257152 -0.83632559 0.08" /> -->
        <!-- test 1.8 -->
        <!-- <origin rpy="0.0 0.0 0.0" xyz="-0.074 -0.87 0.075" /> -->
        <!-- test 1.9 -->
        <!-- <origin rpy="0.0 0.0 0.0" xyz="-0.074 -0.9 0.065" /> -->
        <!-- test 1.10 -->
        <!-- <origin rpy="0.0 0.0 0.0" xyz="-0.174 -0.8 0.115" /> -->
        <!-- test 1.11 -->
        <!-- <origin rpy="0.0 0.0 0.0" xyz="-0.134 -0.81 0.145" /> -->
        <!-- test 1.12 -->
        <!-- <origin rpy="0.0 0.0 0.0" xyz="-0.104 -0.81 0.215" /> -->
        <!-- test 1.13 -->
        <!-- <origin rpy="0.0 0.0 0.0" xyz="0.04767848 -0.72070059 0.07993548" /> -->
        <!-- test 1.14 -->
        <!-- <origin rpy="0.0 0.0 0.0" xyz="0.05312177 -0.124 -0.81 0.19" /> -->
        <!-- test 1.15 -->
        <!-- <origin rpy="0.0 0.0 0.0" xyz="0.04767848 -0.82070059 0.1903548" /> -->
        <!-- test 1.16 -->
        <!-- <origin rpy="0.0 0.0 0.0" xyz="0.04967848 -0.80070059 0.1703548" /> -->
        <!-- test 1.17 -->
        <!-- <origin rpy="0.0 0.0 0.0" xyz="0.05167848 -0.86070059 0.1503548" /> -->
        <!-- test 1.18 -->
        <!-- <origin rpy="0.0 0.0 0.0" xyz="0.05367848 -0.88070059 0.1103548" /> -->
        <!-- test 1.19 -->
        <!-- <origin rpy="0.0 0.0 0.0" xyz="-0.10367848 -0.68070059 0.1303548" /> -->
    </joint>
    <link name="goal_link">
        <visual>
            <geometry>
                <!-- <sphere radius="0.01" /> -->
            </geometry>
            <material name="Brown">
                <color rgba="0.5 0.3 0.1 1.0" />
            </material>
        </visual>
        <collision>
            <geometry>
                <!-- <sphere radius="0.01" /> -->
            </geometry>
        </collision>
        <inertial>
            <mass value="1.0" />
            <inertia ixx="0.01" iyy="0.01" izz="0.01" ixy="0.0" ixz="0.0" iyz="0.0" />
            <origin xyz="0 0 0" rpy="0 0 0" />
        </inertial>
    </link>

    <joint name="base_link_obs_1" type="fixed">
        <parent link="base_link" />
        <child link="obs_1_link" />
        <!-- <origin rpy="0.0 0.0 0.0" xyz="0.04867848 -0.83445059  0.04993548" /> -->
        <!-- test 1.0 -->
        <origin rpy="0.0 0.0 0.0" xyz="0.05312177 -0.82213129  0.11547495" />
    </joint>
    <link name="obs_1_link">
        <visual>
            <geometry>
                <sphere radius="0.01" />
            </geometry>
            <material name="Brown">
                <color rgba="0.5 0.3 0.1 1.0" />
            </material>
        </visual>
        <collision>
            <geometry>
                <sphere radius="0.01" />
            </geometry>
        </collision>
        <inertial>
            <mass value="1.0" />
            <inertia ixx="0.01" iyy="0.01" izz="0.01" ixy="0.0" ixz="0.0" iyz="0.0" />
            <origin xyz="0 0 0" rpy="0 0 0" />
        </inertial>
    </link>
    <gazebo reference="obs_1_link">
        <material>Gazebo/Red</material>
    </gazebo>

    <joint name="base_link_obs_2" type="fixed">
        <parent link="base_link" />
        <child link="obs_2_link" />
        <!-- <origin rpy="0.0 0.0 0.0" xyz="0.04867848 -0.79070059 0.04993548" /> -->
        <!-- test 1.1 -->
        <origin rpy="0.0 0.0 0.0" xyz="-0.035, -0.970, 0.120" />
    </joint>
    <link name="obs_2_link">
        <visual>
            <geometry>
                <sphere radius="0.01" />
            </geometry>
            <material name="Brown">
                <color rgba="0.5 0.3 0.1 1.0" />
            </material>
        </visual>
        <collision>
            <geometry>
                <sphere radius="0.01" />
            </geometry>
        </collision>
        <inertial>
            <mass value="1.0" />
            <inertia ixx="0.01" iyy="0.01" izz="0.01" ixy="0.0" ixz="0.0" iyz="0.0" />
            <origin xyz="0 0 0" rpy="0 0 0" />
        </inertial>
    </link>

    <joint name="base_link_obs_3" type="fixed">
        <parent link="base_link" />
        <child link="obs_3_link" />
        <!-- <origin rpy="0.0 0.0 0.0" xyz="0.00492848 -0.81257559 0.04993548" /> -->
        <!-- test 1.2 -->
        <origin rpy="0.0 0.0 0.0" xyz="0.051 -0.722  0.110" />
    </joint>
    <link name="obs_3_link">
        <visual>
            <geometry>
                <sphere radius="0.01" />
            </geometry>
            <material name="Brown">
                <color rgba="0.5 0.3 0.1 1.0" />
            </material>
        </visual>
        <collision>
            <geometry>
                <sphere radius="0.01" />
            </geometry>
        </collision>
        <inertial>
            <mass value="1.0" />
            <inertia ixx="0.01" iyy="0.01" izz="0.01" ixy="0.0" ixz="0.0" iyz="0.0" />
            <origin xyz="0 0 0" rpy="0 0 0" />
        </inertial>
    </link>


    <joint name="base_link_obs_4" type="fixed">
        <parent link="base_link" />
        <child link="obs_4_link" />
        <!-- <origin rpy="0.0 0.0 0.0" xyz="0.00492848 -0.76882559 0.04993548" /> -->
        <!-- test 1.3 -->
        <origin rpy="0.0 0.0 0.0" xyz="0.054 -0.869 0.13" />
    </joint>
    <link name="obs_4_link">
        <visual>
            <geometry>
                <sphere radius="0.01" />
            </geometry>
            <material name="Brown">
                <color rgba="0.5 0.3 0.1 1.0" />
            </material>
        </visual>
        <collision>
            <geometry>
                <sphere radius="0.01" />
            </geometry>
        </collision>
        <inertial>
            <mass value="1.0" />
            <inertia ixx="0.01" iyy="0.01" izz="0.01" ixy="0.0" ixz="0.0" iyz="0.0" />
            <origin xyz="0 0 0" rpy="0 0 0" />
        </inertial>
    </link>

    <joint name="base_link_obs_5" type="fixed">
        <parent link="base_link" />
        <child link="obs_5_link" />
        <!-- <origin rpy="0.0 0.0 0.0" xyz="0.00492848 -0.85632559 0.04993548" /> -->
        <!-- test 1.7 -->
        <origin rpy="0.0 0.0 0.0" xyz="-0.08257152 -0.83632559 0.08" />
    </joint>
    <link name="obs_5_link">
        <visual>
            <geometry>
                <sphere radius="0.01" />
            </geometry>
            <material name="Brown">
                <color rgba="0.5 0.3 0.1 1.0" />
            </material>
        </visual>
        <collision>
            <geometry>
                <sphere radius="0.01" />
            </geometry>
        </collision>
        <inertial>
            <mass value="1.0" />
            <inertia ixx="0.01" iyy="0.01" izz="0.01" ixy="0.0" ixz="0.0" iyz="0.0" />
            <origin xyz="0 0 0" rpy="0 0 0" />
        </inertial>
    </link>

    <joint name="base_link_obs_6" type="fixed">
        <!-- <parent link="obs_1_link" /> -->
        <parent link="base_link" />
        <child link="obs_6_link" />
        <!-- <origin rpy="0.0 0.0 0.0" xyz="-0.0875 0 0" /> -->
        <!-- test 1.8 -->
        <origin rpy="0.0 0.0 0.0" xyz="-0.074 -0.87 0.075" />
    </joint>

    <link name="obs_6_link">
        <visual>
            <geometry>
                <sphere radius="0.01" />
            </geometry>
            <material name="Brown">
                <color rgba="0.5 0.3 0.1 1.0" />
            </material>
        </visual>
        <collision>
            <geometry>
                <sphere radius="0.01" />
            </geometry>
        </collision>
        <inertial>
            <mass value="1.0" />
            <inertia ixx="0.01" iyy="0.01" izz="0.01" ixy="0.0" ixz="0.0" iyz="0.0" />
            <origin xyz="0 0 0" rpy="0 0 0" />
        </inertial>
    </link>

    <joint name="base_link_obs_7" type="fixed">
        <!-- <parent link="obs_2_link" /> -->
        <parent link="base_link" />
        <child link="obs_7_link" />
        <!-- <origin rpy="0.0 0.0 0.0" xyz="-0.0875 0 0" /> -->
        <!-- test 1.9 -->
        <origin rpy="0.0 0.0 0.0" xyz="-0.074 -0.9 0.065" />
    </joint>

    <link name="obs_7_link">
        <visual>
            <geometry>
                <sphere radius="0.01" />
            </geometry>
            <material name="Brown">
                <color rgba="0.5 0.3 0.1 1.0" />
            </material>
        </visual>
        <collision>
            <geometry>
                <sphere radius="0.01" />
            </geometry>
        </collision>
        <inertial>
            <mass value="1.0" />
            <inertia ixx="0.01" iyy="0.01" izz="0.01" ixy="0.0" ixz="0.0" iyz="0.0" />
            <origin xyz="0 0 0" rpy="0 0 0" />
        </inertial>
    </link>

    <joint name="base_link_obs_8" type="fixed">
        <!-- <parent link="obs_3_link" /> -->
        <parent link="base_link" />
        <child link="obs_8_link" />
        <!-- <origin rpy="0.0 0.0 0.0" xyz="-0.0875 0 0" /> -->
        <!-- test 1.13 -->
        <origin rpy="0.0 0.0 0.0" xyz="0.04767848 -0.72070059 0.07993548" />
    </joint>

    <link name="obs_8_link">
        <visual>
            <geometry>
                <sphere radius="0.01" />
            </geometry>
            <material name="Brown">
                <color rgba="0.5 0.3 0.1 1.0" />
            </material>
        </visual>
        <collision>
            <geometry>
                <sphere radius="0.01" />
            </geometry>
        </collision>
        <inertial>
            <mass value="1.0" />
            <inertia ixx="0.01" iyy="0.01" izz="0.01" ixy="0.0" ixz="0.0" iyz="0.0" />
            <origin xyz="0 0 0" rpy="0 0 0" />
        </inertial>
    </link>

    <joint name="base_link_obs_9" type="fixed">
        <!-- <parent link="obs_4_link" /> -->
        <parent link="base_link" />
        <child link="obs_9_link" />
        <!-- <origin rpy="0.0 0.0 0.0" xyz="-0.0875 0 0" /> -->
        <!-- test 1.15 -->
        <origin rpy="0.0 0.0 0.0" xyz="0.04767848 -0.82070059 0.1903548" />
    </joint>

    <link name="obs_9_link">
        <visual>
            <geometry>
                <sphere radius="0.01" />
            </geometry>
            <material name="Brown">
                <color rgba="0.5 0.3 0.1 1.0" />
            </material>
        </visual>
        <collision>
            <geometry>
                <sphere radius="0.01" />
            </geometry>
        </collision>
        <inertial>
            <mass value="1.0" />
            <inertia ixx="0.01" iyy="0.01" izz="0.01" ixy="0.0" ixz="0.0" iyz="0.0" />
            <origin xyz="0 0 0" rpy="0 0 0" />
        </inertial>
    </link>

    <joint name="base_link_obs_10" type="fixed">
        <parent link="base_link" />
        <child link="obs_10_link" />
        <!-- <origin rpy="0.0 0.0 0.0" xyz="-0.08257152 -0.85632559 0.04993548" /> -->
        <!-- test 1.17 -->
        <origin rpy="0.0 0.0 0.0" xyz="0.05167848 -0.86070059 0.1503548" />
    </joint>
    <link name="obs_10_link">
        <visual>
            <geometry>
                <sphere radius="0.01" />
            </geometry>
            <material name="Brown">
                <color rgba="0.5 0.3 0.1 1.0" />
            </material>
        </visual>
        <collision>
            <geometry>
                <sphere radius="0.01" />
            </geometry>
        </collision>
        <inertial>
            <mass value="1.0" />
            <inertia ixx="0.01" iyy="0.01" izz="0.01" ixy="0.0" ixz="0.0" iyz="0.0" />
            <origin xyz="0 0 0" rpy="0 0 0" />
        </inertial>
    </link>

    <gazebo reference="obs_2_link">
        <material>Gazebo/Blue</material>
    </gazebo>
    <gazebo reference="obs_3_link">
        <material>Gazebo/Black</material>
    </gazebo>
    <gazebo reference="obs_4_link">
        <material>Gazebo/Green</material>
    </gazebo>
    <gazebo reference="obs_5_link">
        <material>Gazebo/Wood</material>
    </gazebo>
    <gazebo reference="obs_6_link">
        <material>Gazebo/Bricks</material>
    </gazebo>
    <gazebo reference="obs_7_link">
        <material>Gazebo/Purple</material>
    </gazebo>
    <gazebo reference="obs_8_link">
        <material>Gazebo/Grey</material>
    </gazebo>
    <gazebo reference="obs_9_link">
        <material>Gazebo/SkyBlue</material>
    </gazebo>
    <gazebo reference="obs_10_link">
        <material>Gazebo/White</material>
    </gazebo>
    


    <joint name="world_stomach_joint" type="fixed">
        <parent link="table_top" />
        <child link="stomach_link" />
        <!-- TODO: check base_link name of robot -->
        <origin rpy="0.0 0.0 -1.570796325" xyz="0.0 -0.27 0.065" />
    </joint>
    <link name="stomach_link">
        <inertial>
            <origin xyz="-0.00116958816636348 0.00194191798200065 0.0163617422794715" rpy="0 0 0" />
            <mass value="1.67854287309931" />
            <inertia ixx="0.0127919503513295" ixy="-0.000351502262622538" ixz="0.000129139947884529"
                iyy="0.0101141052014532" iyz="-2.2641300307581E-05" izz="0.0214244565663922" />
        </inertial>
        <visual>
            <origin xyz="0 0 0" rpy="0 0 0" />
            <geometry>
                <mesh filename="package://round_trainer_edited/meshes/base_link.STL"
                    scale="1.75 1.75 1.75" />
            </geometry>
            <material name="">
                <color rgba="0.752941176470588 0.752941176470588 0.752941176470588 1" />
            </material>
        </visual>
        <collision>
            <origin xyz="0 0 0" rpy="0 0 0" />
            <geometry>
                <mesh filename="package://round_trainer_edited/meshes/base_link.STL"
                    scale="1.75 1.75 1.75" />
            </geometry>
        </collision>
    </link>
    <gazebo reference="stomach_link">
        <material>Gazebo/Orange</material>
    </gazebo>
    <!-- Table Top -->
    <link name="table_top">
        <visual>
            <geometry>
                <box size="1.5 1.0 0.05" />
                <!-- Length: 1.5m, Width: 1 m, Thickness: 0.05m -->
            </geometry>
            <material name="Brown">
                <color rgba="0.5 0.3 0.1 1.0" />
                <!-- Brown color -->
            </material>
        </visual>
        <collision>
            <geometry>
                <box size="1.5 1.0 0.05" />
            </geometry>
        </collision>
        <inertial>
            <mass value="1.0" />
            <!-- Table mass -->
            <inertia ixx="0.01" iyy="0.01" izz="0.01" ixy="0.0" ixz="0.0" iyz="0.0" />
            <origin xyz="0 0 0" rpy="0 0 0" />
        </inertial>
    </link>
    <gazebo reference="table_top">
        <material>Gazebo/Wood</material>
    </gazebo>
    <!-- Table Legs -->
    <link name="table_leg_1">
        <visual>
            <geometry>
                <cylinder length="0.5" radius="0.025" />
                <!-- Height: 0.5m, Radius: 0.025m -->
            </geometry>
            <material name="Brown">
                <color rgba="0.5 0.3 0.1 1.0" />
            </material>
        </visual>
        <collision>
            <geometry>
                <cylinder length="0.5" radius="0.025" />
            </geometry>
        </collision>
        <inertial>
            <mass value="0.1" />
            <inertia ixx="0.001" iyy="0.001" izz="0.001" ixy="0.0" ixz="0.0" iyz="0.0" />
            <origin xyz="0 0 0" rpy="0 0 0" />
        </inertial>
    </link>
    <link name="table_leg_2">
        <visual>
            <geometry>
                <cylinder length="0.5" radius="0.025" />
            </geometry>
            <material name="Brown">
                <color rgba="0.5 0.3 0.1 1.0" />
            </material>
        </visual>
        <collision>
            <geometry>
                <cylinder length="0.5" radius="0.025" />
            </geometry>
        </collision>
        <inertial>
            <mass value="0.1" />
            <inertia ixx="0.001" iyy="0.001" izz="0.001" ixy="0.0" ixz="0.0" iyz="0.0" />
            <origin xyz="0 0 0" rpy="0 0 0" />
        </inertial>
    </link>
    <link name="table_leg_3">
        <visual>
            <geometry>
                <cylinder length="0.5" radius="0.025" />
            </geometry>
            <material name="Brown">
                <color rgba="0.5 0.3 0.1 1.0" />
            </material>
        </visual>
        <collision>
            <geometry>
                <cylinder length="0.5" radius="0.025" />
            </geometry>
        </collision>
        <inertial>
            <mass value="0.1" />
            <inertia ixx="0.001" iyy="0.001" izz="0.001" ixy="0.0" ixz="0.0" iyz="0.0" />
            <origin xyz="0 0 0" rpy="0 0 0" />
        </inertial>
    </link>
    <link name="table_leg_4">
        <visual>
            <geometry>
                <cylinder length="0.5" radius="0.025" />
            </geometry>
            <material name="Brown">
                <color rgba="0.5 0.3 0.1 1.0" />
            </material>
        </visual>
        <collision>
            <geometry>
                <cylinder length="0.5" radius="0.025" />
            </geometry>
        </collision>
        <inertial>
            <mass value="0.1" />
            <inertia ixx="0.001" iyy="0.001" izz="0.001" ixy="0.0" ixz="0.0" iyz="0.0" />
            <origin xyz="0 0 0" rpy="0 0 0" />
        </inertial>
    </link>
    <!-- Joints to connect legs to the table top -->
    <joint name="joint_leg_1" type="fixed">
        <parent link="table_top" />
        <child link="table_leg_1" />
        <origin xyz="-0.65 -0.45 -0.275" rpy="0 0 0" />
    </joint>
    <joint name="joint_leg_2" type="fixed">
        <parent link="table_top" />
        <child link="table_leg_2" />
        <origin xyz="0.65 -0.45 -0.275" rpy="0 0 0" />
    </joint>
    <joint name="joint_leg_3" type="fixed">
        <parent link="table_top" />
        <child link="table_leg_3" />
        <origin xyz="-0.65 0.45 -0.275" rpy="0 0 0" />
    </joint>
    <joint name="joint_leg_4" type="fixed">
        <parent link="table_top" />
        <child link="table_leg_4" />
        <origin xyz="0.65 0.45 -0.275" rpy="0 0 0" />
    </joint>
    <!-- <gazebo>
        <self_collide>true</self_collide>
    </gazebo> -->
</robot>